Workbook

Sheet PAINEL
A1: CONTROLE DE CARREGAMENTO ULTRAPÃO
A3: RESUMO GERAL | D3: ESTATÍSTICAS POR VEÍCULO
A4: Total de Itens Bipados: | B4: =COUNTA(BASE!A:A)-1 -> 844 | D4: Veículo | E4: Itens Carregados
A5: Total de Itens Carregados: | B5: =COUNTIF(BASE!F:F, "CARREGADO") -> 0
A6: Total de Itens Únicos: | B6: =COUNTA(CONFERENCIA!A:A)-1 -> 999
A7: Total de Divergências: | B7: =COUNTA(DIVERGÊNCIAS!A:A)-1 -> 999
A10: ACESSO RÁPIDO ÀS ABAS
A11: BASE | B11: Cadastro de produtos bipados
A12: CONFERENCIA | B12: Conferência sem repetir códigos
A13: EXTRATO | B13: Relação de itens carregados
A14: ROMANEIO POR ITEM | B14: Conferência com romaneio
A15: DIVERGÊNCIAS | B15: Lista de divergências encontradas
A17: INSTRUÇÕES DE USO
A18: 1. Na aba BASE, registre todos os produtos bipados com código de barras, produto, quantidade, data/hora, veículo e status
A19: 2. A aba CONFERENCIA consolida automaticamente os itens sem repetir códigos de barras
A20: 3. A aba EXTRATO mostra apenas os itens com status 'CARREGADO'
A21: 4. Na aba ROMANEIO POR ITEM, insira manualmente a quantidade do romaneio na coluna D para comparar
A22: 5. A aba DIVERGÊNCIAS mostra automaticamente todas as diferenças encontradas

Sheet BASE
A1: Codigo | B1: Descricao | C1: Tipo | D1: Unidade | E1: Ult. Preco | F1: Ult. Compra | G1: Peso Bruto | H1: Peso Liquido | I1: Peso Cubado | J1: Cod. EAN-13 | K1: Cod. DUN-14
A2: 2000 | B2: GRAMPEADOR | D2: CX | J2: 7896886499716
A3: 01.01.0001 | B3: MASSA CONGELADA DE PAO FRANCES RAPIDA - 5KG | C3: ME | D3: PT | E3: 34.52 | F3: 46070 | G3: 5.018 | H3: 5 | I3: 5 | J3: 7898694171204 | K3: 17898694171201
A4: 01.01.0002 | B4: MASSA CONGELADA DE PAO FRANCES MEDIA - 5KG | C4: ME | D4: PT | E4: 34.73 | F4: 46070 | G4: 5 | H4: 5 | I4: 5 | J4: 7898694171211 | K4: 17898694171218
A5: 01.01.0003 | B5: MASSA CONGELADA DE PAO FRANCES RAPIDA 65G - 5KG | C5: ME | D5: PT | E5: 0 | G5: 5 | H5: 5 | I5: 0 | J5: 7898694171365 | K5: 7898694171365
A6: 01.01.0004 | B6: MASSA CONGELADA DE PAO FRANCES MEDIA 65G - 5KG | C6: ME | D6: PT | E6: 0 | G6: 5 | H6: 5 | I6: 0 | J6: 7898694171372 | K6: 7898694171372
A7: 01.01.0005 | B7: MASSA CONGELADA DE PAO FRANCES BENJAMIN - 5KG | C7: ME | D7: PT | E7: 0 | G7: 5 | H7: 5 | I7: 5 | J7: 7898694171228 | K7: 7898694171228
A8: 01.01.0006 | B8: MASSA CONGELADA DE PAO FRANCES RAPIDA - 10KG | C8: ME | D8: PT | E8: 0 | G8: 5 | H8: 5 | I8: 12 | J8: 17898694171201 | K8: 17898694171201
A9: 01.01.0007 | B9: MASSA CONGELADA DE PAO FRANCES RAPIDA - CX 20KG - 4 UN DE 5KG | C9: ME | D9: CX | E9: 0 | G9: 20.55 | H9: 20 | I9: 0 | J9: 37898694171205
A10: 01.01.0008 | B10: MASSA CONGELADA DE PAO FRANCES RAPIDA - 10 KG | C10: ME | D10: PT | E10: 0 | G10: 0 | H10: 0 | I10: 0
A11: 01.01.1001 | B11: MASSA CONGELADA DE PAO FRANCES RAPIDA (KG) | C11: ME | D11: KG | E11: 0 | G11: 10.01 | H11: 10 | I11: 10.01 | J11: 7898694172805 | K11: 7898694172805
A12: 01.01.1002 | B12: MASSA CONGELADA DE PAO FRANCES MEDIA (KG) | C12: ME | D12: KG | E12: 0 | G12: 10.01 | H12: 10 | I12: 10.01 | J12: 7898694173512 | K12: 7898694173512
A13: 01.02.0001 | B13: MASSA CONGELADA DE MINI PAO FRANCES RAPIDA - 5KG | C13: ME | D13: PT | E13: 36.89 | F13: 46027 | G13: 5 | H13: 5 | I13: 5 | J13: 17898694171263 | K13: 17898694171263
A14: 01.02.0002 | B14: MASSA CONGELADA DE MINI PAO FRANCES MEDIA - 5KG | C14: ME | D14: PT | E14: 0 | G14: 5 | H14: 5 | I14: 0 | J14: 7898694171402 | K14: 7898694171402
A15: 01.02.0003 | B15: MASSA CONGELADA DE MINI PAO FRANCES INTEGRAL RAPIDA - 5KG | C15: ME | D15: PT | E15: 24 | F15: 45930 | G15: 5 | H15: 5 | I15: 5 | J15: 17898694171270 | K15: 17898694171270
A16: 01.02.0004 | B16: MASSA CONGELADA DE MINI PAO FRANCES INTEGRAL MEDIA - 5KG | C16: ME | D16: PT | E16: 0 | G16: 5 | H16: 5 | I16: 0 | J16: 7898694171433 | K16: 7898694171433
A17: 01.02.0005 | B17: MASSA CONGELADA DE PAO FRANCES INTEGRAL RAPIDA - 5KG | C17: ME | D17: PT | E17: 38.72 | F17: 46070 | G17: 5 | H17: 5 | I17: 5 | J17: 17898694171232 | K17: 17898694171232
A18: 01.02.0006 | B18: MASSA CONGELADA DE PAO FRANCES INTEGRAL MEDIA - 5KG | C18: ME | D18: PT | E18: 0 | G18: 5 | H18: 5 | I18: 0 | J18: 7898694171242 | K18: 7898694171242
A19: 01.02.0007 | B19: MASSA CONGELADA DE PAO FRANCES COM GRAOS RAPIDA - 5KG | C19: ME | D19: PT | E19: 45.2 | F19: 46069 | G19: 5 | H19: 5 | I19: 5 | J19: 7898694171341
A20: 01.02.0008 | B20: MASSA CONGELADA DE PAO FRANCES COM GRAOS MEDIA - 5KG | C20: ME | D20: PT | E20: 0 | G20: 5 | H20: 5 | I20: 0 | J20: 7898694171464 | K20: 7898694171464
A21: 01.02.0009 | B21: MASSA CONGELADA DE BAGUETE RAPIDA - 5KG | C21: ME | D21: PT | E21: 24.75 | F21: 46065 | G21: 5 | H21: 5 | I21: 5 | J21: 7898694171327 | K21: 7898694171327
A22: 01.02.0010 | B22: MASSA CONGELADA DE BAGUETE MEDIA - 5KG | C22: ME | D22: PT | E22: 0 | G22: 5 | H22: 5 | I22: 0 | J22: 7898694171426 | K22: 7898694171426
A23: 01.02.0011 | B23: MASSA CONGELADA DE MINI BAGUETE RAPIDA - 5KG | C23: ME | D23: PT | E23: 24.75 | F23: 46065 | G23: 5 | H23: 5 | I23: 5 | J23: 7898694171280
A24: 01.02.0012 | B24: MASSA CONGELADA DE MINI BAGUETE MEDIA - 5KG | C24: ME | D24: PT | E24: 0 | G24: 5 | H24: 5 | I24: 0 | J24: 7898694171419 | K24: 7898694171419
A25: 01.02.0013 | B25: MASSA CONGELADA DE BAGUETE INTEGRAL RAPIDA - 5KG | C25: ME | D25: PT | E25: 0 | G25: 5 | H25: 5 | I25: 0 | J25: 7898694171396 | K25: 7898694171396
A26: 01.02.0014 | B26: MASSA CONGELADA DE BAGUETE INTEGRAL MEDIA - 5KG | C26: ME | D26: PT | E26: 0 | G26: 5 | H26: 5 | I26: 0 | J26: 7898694171457 | K26: 7898694171457
A27: 01.02.0015 | B27: MASSA CONGELADA DE MINI BAGUETE INTEGRAL RAPIDA - 5KG | C27: ME | D27: PT | E27: 0 | G27: 5 | H27: 5 | I27: 0 | J27: 7898694171297 | K27: 7898694171297
A28: 01.02.0016 | B28: MASSA CONGELADA DE MINI BAGUETE INTEGRAL MEDIA - 5KG | C28: ME | D28: PT | E28: 0 | G28: 5 | H28: 5 | I28: 0 | J28: 7898694171440 | K28: 7898694171440
A29: 01.02.0017 | B29: MASSA CONGELADA DE PAO FRANCES BOLA RAPIDA - 5KG | C29: ME | D29: PT | E29: 0 | G29: 5 | H29: 5 | I29: 0
A30: 01.02.0018 | B30: MASSA CONGELADA DE BENZINHO BENJAMIN - 4KG | C30: ME | D30: PT | E30: 0 | G30: 4 | H30: 4 | I30: 5
A31: 01.02.0019 | B31: MASSA CONGELADA DE BENZINHO BENJAMIN - 5KG | C31: ME | D31: PT | E31: 0 | G31: 5 | H31: 5 | I31: 0 | J31: 7898694171389 | K31: 7898694171389
A32: 01.02.0020 | B32: MASSA CONGELADA DE PAO FRANCES INTEGRAL BENJAMIN - 5KG | C32: ME | D32: PT | E32: 0 | G32: 5 | H32: 5 | I32: 0 | J32: 7898694171259 | K32: 7898694171259
A33: 01.02.0021 | B33: MASSA CONGELADA DE PAO FRANCES COM GRAOS BENJAMIN - 5KG | C33: ME | D33: PT | E33: 0 | G33: 5 | H33: 5 | I33: 5 | J33: 7898694171341 | K33: 7898694171341
A34: 01.02.0022 | B34: MASSA CONGELADA DE MINI BAGUETE BENJAMIN - 5KG | C34: ME | D34: PT | E34: 0 | G34: 5 | H34: 5 | I34: 0 | J34: 7898694171303 | K34: 7898694171303
A35: 01.02.0023 | B35: MASSA CONGELADA DE MINI BAGUETE INTEGRAL BENJAMIN - 5KG | C35: ME | D35: PT | E35: 0 | G35: 5 | H35: 5 | I35: 0 | J35: 7898694171310 | K35: 7898694171310
A36: 01.02.0024 | B36: MASSA CONGELADA DE MINI BAGUETE COM PARMESAO BENJAMIN - 5KG | C36: ME | D36: PT | E36: 0 | G36: 5 | H36: 5 | I36: 0
A37: 01.02.0025 | B37: MASSA CONGELADA DE PAO FRANCES INTEGRAL RAPIDA - 10KG | C37: ME | D37: CX | E37: 0 | G37: 0 | H37: 10 | I37: 12
A38: 01.02.0026 | B38: MASSA CONGELADA DE PAO FRANCES COM GRAOS RAPIDA - CX 10KG - 2 UN DE 5KG | C38: ME | D38: CX | E38: 0 | G38: 10 | H38: 10 | I38: 0 | J38: 178986941713486 | K38: 78986941713418
A39: 01.02.0027 | B39: MASSA CONGELADA DE MINI PAO FRANCES RAPIDA - CX 10KG - 2 UN DE 5KG | C39: ME | D39: CX | E39: 20.5 | F39: 45338 | G39: 10.36 | H39: 10 | I39: 0
A40: 01.02.0028 | B40: MASSA CONGELADA DE BAGUETE RAPIDA - CX 10KG - 2 UN DE 5KG | C40: ME | D40: CX | E40: 20.5 | F40: 45322 | G40: 10.63 | H40: 10 | I40: 0 | K40: 27898694171321
...

Sheet CONFERENCIA
A1: CÓDIGO DE BARRAS | B1: PRODUTO | C1: QUANTIDADE TOTAL | D1: ÚLTIMA DATA/HORA | E1: VEÍCULO
A2: 7896886499716 | B2: =IF(A2="", "", VLOOKUP(A2, BASE!$A$4:$B$10003, 2, FALSE)) -> #N/A | C2: =IF(A2="", "", SUMIF(BASE!$A$4:$A$10003, A2, BASE!$C$4:$C$10003)) -> 0 | D2: =IF(A2="", "", INDEX(BASE!$D$4:$D$10003, MATCH(A2, BASE!$A$4:$A$10003, 0))) -> #N/A | E2: =IF(A2="", "", INDEX(BASE!$E$4:$E$10003, MATCH(A2, BASE!$A$4:$A$10003, 0))) -> #N/A
A3: 7896886499716 | B3: =IF(A3="", "", VLOOKUP(A3, BASE!$A$4:$B$10003, 2, FALSE)) -> #N/A | C3: =IF(A3="", "", SUMIF(BASE!$A$4:$A$10003, A3, BASE!$C$4:$C$10003)) -> 0 | D3: =IF(A3="", "", INDEX(BASE!$D$4:$D$10003, MATCH(A3, BASE!$A$4:$A$10003, 0))) -> #N/A | E3: =IF(A3="", "", INDEX(BASE!$E$4:$E$10003, MATCH(A3, BASE!$A$4:$A$10003, 0))) -> #N/A
A4: =IFERROR(INDEX(BASE!$A$4:$A$10003, MATCH(0, COUNTIF($A$1:A3, BASE!$A$4:$A$10003&""), 0)), "") | B4: =IF(A4="", "", VLOOKUP(A4, BASE!$A$4:$B$10003, 2, FALSE)) | C4: =IF(A4="", "", SUMIF(BASE!$A$4:$A$10003, A4, BASE!$C$4:$C$10003)) | D4: =IF(A4="", "", INDEX(BASE!$D$4:$D$10003, MATCH(A4, BASE!$A$4:$A$10003, 0))) | E4: =IF(A4="", "", INDEX(BASE!$E$4:$E$10003, MATCH(A4, BASE!$A$4:$A$10003, 0)))
A5: =IFERROR(INDEX(BASE!$A$4:$A$10003, MATCH(0, COUNTIF($A$1:A4, BASE!$A$4:$A$10003&""), 0)), "") | B5: =IF(A5="", "", VLOOKUP(A5, BASE!$A$4:$B$10003, 2, FALSE)) | C5: =IF(A5="", "", SUMIF(BASE!$A$4:$A$10003, A5, BASE!$C$4:$C$10003)) | D5: =IF(A5="", "", INDEX(BASE!$D$4:$D$10003, MATCH(A5, BASE!$A$4:$A$10003, 0))) | E5: =IF(A5="", "", INDEX(BASE!$E$4:$E$10003, MATCH(A5, BASE!$A$4:$A$10003, 0)))
A6: =IFERROR(INDEX(BASE!$A$4:$A$10003, MATCH(0, COUNTIF($A$1:A5, BASE!$A$4:$A$10003&""), 0)), "") | B6: =IF(A6="", "", VLOOKUP(A6, BASE!$A$4:$B$10003, 2, FALSE)) | C6: =IF(A6="", "", SUMIF(BASE!$A$4:$A$10003, A6, BASE!$C$4:$C$10003)) | D6: =IF(A6="", "", INDEX(BASE!$D$4:$D$10003, MATCH(A6, BASE!$A$4:$A$10003, 0))) | E6: =IF(A6="", "", INDEX(BASE!$E$4:$E$10003, MATCH(A6, BASE!$A$4:$A$10003, 0)))
A7: =IFERROR(INDEX(BASE!$A$4:$A$10003, MATCH(0, COUNTIF($A$1:A6, BASE!$A$4:$A$10003&""), 0)), "") | B7: =IF(A7="", "", VLOOKUP(A7, BASE!$A$4:$B$10003, 2, FALSE)) | C7: =IF(A7="", "", SUMIF(BASE!$A$4:$A$10003, A7, BASE!$C$4:$C$10003)) | D7: =IF(A7="", "", INDEX(BASE!$D$4:$D$10003, MATCH(A7, BASE!$A$4:$A$10003, 0))) | E7: =IF(A7="", "", INDEX(BASE!$E$4:$E$10003, MATCH(A7, BASE!$A$4:$A$10003, 0)))
A8: =IFERROR(INDEX(BASE!$A$4:$A$10003, MATCH(0, COUNTIF($A$1:A7, BASE!$A$4:$A$10003&""), 0)), "") | B8: =IF(A8="", "", VLOOKUP(A8, BASE!$A$4:$B$10003, 2, FALSE)) | C8: =IF(A8="", "", SUMIF(BASE!$A$4:$A$10003, A8, BASE!$C$4:$C$10003)) | D8: =IF(A8="", "", INDEX(BASE!$D$4:$D$10003, MATCH(A8, BASE!$A$4:$A$10003, 0))) | E8: =IF(A8="", "", INDEX(BASE!$E$4:$E$10003, MATCH(A8, BASE!$A$4:$A$10003, 0)))
A9: =IFERROR(INDEX(BASE!$A$4:$A$10003, MATCH(0, COUNTIF($A$1:A8, BASE!$A$4:$A$10003&""), 0)), "") | B9: =IF(A9="", "", VLOOKUP(A9, BASE!$A$4:$B$10003, 2, FALSE)) | C9: =IF(A9="", "", SUMIF(BASE!$A$4:$A$10003, A9, BASE!$C$4:$C$10003)) | D9: =IF(A9="", "", INDEX(BASE!$D$4:$D$10003, MATCH(A9, BASE!$A$4:$A$10003, 0))) | E9: =IF(A9="", "", INDEX(BASE!$E$4:$E$10003, MATCH(A9, BASE!$A$4:$A$10003, 0)))
A10: =IFERROR(INDEX(BASE!$A$4:$A$10003, MATCH(0, COUNTIF($A$1:A9, BASE!$A$4:$A$10003&""), 0)), "") | B10: =IF(A10="", "", VLOOKUP(A10, BASE!$A$4:$B$10003, 2, FALSE)) | C10: =IF(A10="", "", SUMIF(BASE!$A$4:$A$10003, A10, BASE!$C$4:$C$10003)) | D10: =IF(A10="", "", INDEX(BASE!$D$4:$D$10003, MATCH(A10, BASE!$A$4:$A$10003, 0))) | E10: =IF(A10="", "", INDEX(BASE!$E$4:$E$10003, MATCH(A10, BASE!$A$4:$A$10003, 0)))
A11: =IFERROR(INDEX(BASE!$A$4:$A$10003, MATCH(0, COUNTIF($A$1:A10, BASE!$A$4:$A$10003&""), 0)), "") | B11: =IF(A11="", "", VLOOKUP(A11, BASE!$A$4:$B$10003, 2, FALSE)) | C11: =IF(A11="", "", SUMIF(BASE!$A$4:$A$10003, A11, BASE!$C$4:$C$10003)) | D11: =IF(A11="", "", INDEX(BASE!$D$4:$D$10003, MATCH(A11, BASE!$A$4:$A$10003, 0))) | E11: =IF(A11="", "", INDEX(BASE!$E$4:$E$10003, MATCH(A11, BASE!$A$4:$A$10003, 0)))
A12: =IFERROR(INDEX(BASE!$A$4:$A$10003, MATCH(0, COUNTIF($A$1:A11, BASE!$A$4:$A$10003&""), 0)), "") | B12: =IF(A12="", "", VLOOKUP(A12, BASE!$A$4:$B$10003, 2, FALSE)) | C12: =IF(A12="", "", SUMIF(BASE!$A$4:$A$10003, A12, BASE!$C$4:$C$10003)) | D12: =IF(A12="", "", INDEX(BASE!$D$4:$D$10003, MATCH(A12, BASE!$A$4:$A$10003, 0))) | E12: =IF(A12="", "", INDEX(BASE!$E$4:$E$10003, MATCH(A12, BASE!$A$4:$A$10003, 0)))
A13: =IFERROR(INDEX(BASE!$A$4:$A$10003, MATCH(0, COUNTIF($A$1:A12, BASE!$A$4:$A$10003&""), 0)), "") | B13: =IF(A13="", "", VLOOKUP(A13, BASE!$A$4:$B$10003, 2, FALSE)) | C13: =IF(A13="", "", SUMIF(BASE!$A$4:$A$10003, A13, BASE!$C$4:$C$10003)) | D13: =IF(A13="", "", INDEX(BASE!$D$4:$D$10003, MATCH(A13, BASE!$A$4:$A$10003, 0))) | E13: =IF(A13="", "", INDEX(BASE!$E$4:$E$10003, MATCH(A13, BASE!$A$4:$A$10003, 0)))
A14: =IFERROR(INDEX(BASE!$A$4:$A$10003, MATCH(0, COUNTIF($A$1:A13, BASE!$A$4:$A$10003&""), 0)), "") | B14: =IF(A14="", "", VLOOKUP(A14, BASE!$A$4:$B$10003, 2, FALSE)) | C14: =IF(A14="", "", SUMIF(BASE!$A$4:$A$10003, A14, BASE!$C$4:$C$10003)) | D14: =IF(A14="", "", INDEX(BASE!$D$4:$D$10003, MATCH(A14, BASE!$A$4:$A$10003, 0))) | E14: =IF(A14="", "", INDEX(BASE!$E$4:$E$10003, MATCH(A14, BASE!$A$4:$A$10003, 0)))
A15: =IFERROR(INDEX(BASE!$A$4:$A$10003, MATCH(0, COUNTIF($A$1:A14, BASE!$A$4:$A$10003&""), 0)), "") | B15: =IF(A15="", "", VLOOKUP(A15, BASE!$A$4:$B$10003, 2, FALSE)) | C15: =IF(A15="", "", SUMIF(BASE!$A$4:$A$10003, A15, BASE!$C$4:$C$10003)) | D15: =IF(A15="", "", INDEX(BASE!$D$4:$D$10003, MATCH(A15, BASE!$A$4:$A$10003, 0))) | E15: =IF(A15="", "", INDEX(BASE!$E$4:$E$10003, MATCH(A15, BASE!$A$4:$A$10003, 0)))
... A1000: =IFERROR(INDEX(BASE!$A$4:$A$10003, MATCH(0, COUNTIF($A$1:A999, BASE!$A$4:$A$10003&""), 0)), "") | B1000: =IF(A1000="", "", VLOOKUP(A1000, BASE!$A$4:$B$10003, 2, FALSE)) | C1000: =IF(A1000="", "", SUMIF(BASE!$A$4:$A$10003, A1000, BASE!$C$4:$C$10003)) | D1000: =IF(A1000="", "", INDEX(BASE!$D$4:$D$10003, MATCH(A1000, BASE!$A$4:$A$10003, 0))) | E1000: =IF(A1000="", "", INDEX(BASE!$E$4:$E$10003, MATCH(A1000, BASE!$A$4:$A$10003, 0)))

Sheet EXTRATO
A1: CÓDIGO DE BARRAS | B1: PRODUTO | C1: QUANTIDADE | D1: DATA/HORA | E1: VEÍCULO | F1: STATUS
A2: =IFERROR(INDEX(BASE!$A$4:$A$10003, SMALL(IF(BASE!$F$4:$F$10003="CARREGADO", ROW(BASE!$A$4:$A$10003)-ROW(BASE!$A$4)+1), ROW(A1))), "") | B2: =IF(A2="", "", VLOOKUP(A2, BASE!$A$4:$B$10003, 2, FALSE)) | C2: =IF(A2="", "", VLOOKUP(A2, BASE!$A$4:$C$10003, 3, FALSE)) | D2: =IF(A2="", "", VLOOKUP(A2, BASE!$A$4:$D$10003, 4, FALSE)) | E2: =IF(A2="", "", VLOOKUP(A2, BASE!$A$4:$E$10003, 5, FALSE)) | F2: =IF(A2="", "", "CARREGADO")
A3: =IFERROR(INDEX(BASE!$A$4:$A$10003, SMALL(IF(BASE!$F$4:$F$10003="CARREGADO", ROW(BASE!$A$4:$A$10003)-ROW(BASE!$A$4)+1), ROW(A2))), "") | B3: =IF(A3="", "", VLOOKUP(A3, BASE!$A$4:$B$10003, 2, FALSE)) | C3: =IF(A3="", "", VLOOKUP(A3, BASE!$A$4:$C$10003, 3, FALSE)) | D3: =IF(A3="", "", VLOOKUP(A3, BASE!$A$4:$D$10003, 4, FALSE)) | E3: =IF(A3="", "", VLOOKUP(A3, BASE!$A$4:$E$10003, 5, FALSE)) | F3: =IF(A3="", "", "CARREGADO")
A4: =IFERROR(INDEX(BASE!$A$4:$A$10003, SMALL(IF(BASE!$F$4:$F$10003="CARREGADO", ROW(BASE!$A$4:$A$10003)-ROW(BASE!$A$4)+1), ROW(A3))), "") | B4: =IF(A4="", "", VLOOKUP(A4, BASE!$A$4:$B$10003, 2, FALSE)) | C4: =IF(A4="", "", VLOOKUP(A4, BASE!$A$4:$C$10003, 3, FALSE)) | D4: =IF(A4="", "", VLOOKUP(A4, BASE!$A$4:$D$10003, 4, FALSE)) | E4: =IF(A4="", "", VLOOKUP(A4, BASE!$A$4:$E$10003, 5, FALSE)) | F4: =IF(A4="", "", "CARREGADO")
A5: =IFERROR(INDEX(BASE!$A$4:$A$10003, SMALL(IF(BASE!$F$4:$F$10003="CARREGADO", ROW(BASE!$A$4:$A$10003)-ROW(BASE!$A$4)+1), ROW(A4))), "") | B5: =IF(A5="", "", VLOOKUP(A5, BASE!$A$4:$B$10003, 2, FALSE)) | C5: =IF(A5="", "", VLOOKUP(A5, BASE!$A$4:$C$10003, 3, FALSE)) | D5: =IF(A5="", "", VLOOKUP(A5, BASE!$A$4:$D$10003, 4, FALSE)) | E5: =IF(A5="", "", VLOOKUP(A5, BASE!$A$4:$E$10003, 5, FALSE)) | F5: =IF(A5="", "", "CARREGADO")
A6: =IFERROR(INDEX(BASE!$A$4:$A$10003, SMALL(IF(BASE!$F$4:$F$10003="CARREGADO", ROW(BASE!$A$4:$A$10003)-ROW(BASE!$A$4)+1), ROW(A5))), "") | B6: =IF(A6="", "", VLOOKUP(A6, BASE!$A$4:$B$10003, 2, FALSE)) | C6: =IF(A6="", "", VLOOKUP(A6, BASE!$A$4:$C$10003, 3, FALSE)) | D6: =IF(A6="", "", VLOOKUP(A6, BASE!$A$4:$D$10003, 4, FALSE)) | E6: =IF(A6="", "", VLOOKUP(A6, BASE!$A$4:$E$10003, 5, FALSE)) | F6: =IF(A6="", "", "CARREGADO")
A7: =IFERROR(INDEX(BASE!$A$4:$A$10003, SMALL(IF(BASE!$F$4:$F$10003="CARREGADO", ROW(BASE!$A$4:$A$10003)-ROW(BASE!$A$4)+1), ROW(A6))), "") | B7: =IF(A7="", "", VLOOKUP(A7, BASE!$A$4:$B$10003, 2, FALSE)) | C7: =IF(A7="", "", VLOOKUP(A7, BASE!$A$4:$C$10003, 3, FALSE)) | D7: =IF(A7="", "", VLOOKUP(A7, BASE!$A$4:$D$10003, 4, FALSE)) | E7: =IF(A7="", "", VLOOKUP(A7, BASE!$A$4:$E$10003, 5, FALSE)) | F7: =IF(A7="", "", "CARREGADO")
A8: =IFERROR(INDEX(BASE!$A$4:$A$10003, SMALL(IF(BASE!$F$4:$F$10003="CARREGADO", ROW(BASE!$A$4:$A$10003)-ROW(BASE!$A$4)+1), ROW(A7))), "") | B8: =IF(A8="", "", VLOOKUP(A8, BASE!$A$4:$B$10003, 2, FALSE)) | C8: =IF(A8="", "", VLOOKUP(A8, BASE!$A$4:$C$10003, 3, FALSE)) | D8: =IF(A8="", "", VLOOKUP(A8, BASE!$A$4:$D$10003, 4, FALSE)) | E8: =IF(A8="", "", VLOOKUP(A8, BASE!$A$4:$E$10003, 5, FALSE)) | F8: =IF(A8="", "", "CARREGADO")
A9: =IFERROR(INDEX(BASE!$A$4:$A$10003, SMALL(IF(BASE!$F$4:$F$10003="CARREGADO", ROW(BASE!$A$4:$A$10003)-ROW(BASE!$A$4)+1), ROW(A8))), "") | B9: =IF(A9="", "", VLOOKUP(A9, BASE!$A$4:$B$10003, 2, FALSE)) | C9: =IF(A9="", "", VLOOKUP(A9, BASE!$A$4:$C$10003, 3, FALSE)) | D9: =IF(A9="", "", VLOOKUP(A9, BASE!$A$4:$D$10003, 4, FALSE)) | E9: =IF(A9="", "", VLOOKUP(A9, BASE!$A$4:$E$10003, 5, FALSE)) | F9: =IF(A9="", "", "CARREGADO")
A10: =IFERROR(INDEX(BASE!$A$4:$A$10003, SMALL(IF(BASE!$F$4:$F$10003="CARREGADO", ROW(BASE!$A$4:$A$10003)-ROW(BASE!$A$4)+1), ROW(A9))), "") | B10: =IF(A10="", "", VLOOKUP(A10, BASE!$A$4:$B$10003, 2, FALSE)) | C10: =IF(A10="", "", VLOOKUP(A10, BASE!$A$4:$C$10003, 3, FALSE)) | D10: =IF(A10="", "", VLOOKUP(A10, BASE!$A$4:$D$10003, 4, FALSE)) | E10: =IF(A10="", "", VLOOKUP(A10, BASE!$A$4:$E$10003, 5, FALSE)) | F10: =IF(A10="", "", "CARREGADO")
A11: =IFERROR(INDEX(BASE!$A$4:$A$10003, SMALL(IF(BASE!$F$4:$F$10003="CARREGADO", ROW(BASE!$A$4:$A$10003)-ROW(BASE!$A$4)+1), ROW(A10))), "") | B11: =IF(A11="", "", VLOOKUP(A11, BASE!$A$4:$B$10003, 2, FALSE)) | C11: =IF(A11="", "", VLOOKUP(A11, BASE!$A$4:$C$10003, 3, FALSE)) | D11: =IF(A11="", "", VLOOKUP(A11, BASE!$A$4:$D$10003, 4, FALSE)) | E11: =IF(A11="", "", VLOOKUP(A11, BASE!$A$4:$E$10003, 5, FALSE)) | F11: =IF(A11="", "", "CARREGADO")
A12: =IFERROR(INDEX(BASE!$A$4:$A$10003, SMALL(IF(BASE!$F$4:$F$10003="CARREGADO", ROW(BASE!$A$4:$A$10003)-ROW(BASE!$A$4)+1), ROW(A11))), "") | B12: =IF(A12="", "", VLOOKUP(A12, BASE!$A$4:$B$10003, 2, FALSE)) | C12: =IF(A12="", "", VLOOKUP(A12, BASE!$A$4:$C$10003, 3, FALSE)) | D12: =IF(A12="", "", VLOOKUP(A12, BASE!$A$4:$D$10003, 4, FALSE)) | E12: =IF(A12="", "", VLOOKUP(A12, BASE!$A$4:$E$10003, 5, FALSE)) | F12: =IF(A12="", "", "CARREGADO")
A13: =IFERROR(INDEX(BASE!$A$4:$A$10003, SMALL(IF(BASE!$F$4:$F$10003="CARREGADO", ROW(BASE!$A$4:$A$10003)-ROW(BASE!$A$4)+1), ROW(A12))), "") | B13: =IF(A13="", "", VLOOKUP(A13, BASE!$A$4:$B$10003, 2, FALSE)) | C13: =IF(A13="", "", VLOOKUP(A13, BASE!$A$4:$C$10003, 3, FALSE)) | D13: =IF(A13="", "", VLOOKUP(A13, BASE!$A$4:$D$10003, 4, FALSE)) | E13: =IF(A13="", "", VLOOKUP(A13, BASE!$A$4:$E$10003, 5, FALSE)) | F13: =IF(A13="", "", "CARREGADO")
... A1000: =IFERROR(INDEX(BASE!$A$4:$A$10003, SMALL(IF(BASE!$F$4:$F$10003="CARREGADO", ROW(BASE!$A$4:$A$10003)-ROW(BASE!$A$4)+1), ROW(A999))), "") | B1000: =IF(A1000="", "", VLOOKUP(A1000, BASE!$A$4:$B$10003, 2, FALSE)) | C1000: =IF(A1000="", "", VLOOKUP(A1000, BASE!$A$4:$C$10003, 3, FALSE)) | D1000: =IF(A1000="", "", VLOOKUP(A1000, BASE!$A$4:$D$10003, 4, FALSE)) | E1000: =IF(A1000="", "", VLOOKUP(A1000, BASE!$A$4:$E$10003, 5, FALSE)) | F1000: =IF(A1000="", "", "CARREGADO")

Sheet COLABORADORES
A1: Centro de Custo | B1: Função | C1: Colaborador
A2: Armazenagem GRU | B2: Conferente | C2: ALEXANDRO BISPO SANTANA
A3: Armazenagem GRU | B3: coordenadora | C3: Astrogildo Rodrigues Dos S
A4: Armazenagem GRU | B4: Auxiliar de Logística | C4: BRUNO BARROS DE OLIVEIRA
A5: Armazenagem GRU | B5: Operador de Empilhadeira | C5: EDI CARLOS ROSENDE BORGES
A6: Armazenagem GRU | B6: aux de estoque | C6: Igor Gomes Dos Santos Rosa
A7: Armazenagem GRU | B7: Auxiliar de Logística | C7: ITALO MATHEUS PEREIRA LIMA CRUZ
A8: Armazenagem GRU | B8: aux de estoque | C8: Jorge Eduardo Rezende
A9: Armazenagem GRU | B9: coordenadora | C9: Joyce Cabral Do Nascimento
A10: Armazenagem GRU | B10: aux de estoque | C10: Leandro M Ferreira Dos Santos
A11: Armazenagem GRU | B11: aux de estoque | C11: Marcelo Silva De Medeiros
A12: Armazenagem GRU | B12: aux de estoque | C12: Marcone Gomes Do Nascimento
... A61: Transporte GRU | B61: Yuri Ravell Feitoza do Nascimento | C61: YURI RAVELL FEITOZA DO NASCIMENTO
B65: 46056
B66: 46145
B67: 89

Sheet ROMANEIO POR ITEM
A1: Data de cadastro | B1: Id roteiro | C1: Identificador da rota | D1: Id viagem faturada | E1: Entrega estimada | F1: Placa | G1: Pedido | H1: Código cliente | I1: Cliente | J1: Tipo cliente | K1: Transportadora | L1: Endereço | M1: Bairro | N1: Cidade | O1: Código do produto | P1: Descrição do produto | Q1: Quantidade do produto | R1: Qtd. caixas | S1: Unidade de medida do produto | T1: Peso bruto pedido | U1: Início previsto | V1: Unidade | W1: Valor total pedido | X1: Peso do veículo | Y1: Motorista
A2: 46066.424 | B2: 555555 | C2: 14 - PPY - VARGINHA | D2: 555555 | F2: ULP0002 | G2: 9999999 | H2: 47380171000157 | I2: CD Guarulhos (Ultrapão) | K2: Ultrapão Transportes | L2: Avenida Faustino Ramalho | M2: Vila Galvão | N2: Guarulhos | O2: 3000 | P2: kit baloes | Q2: 3 | S2: CX | T2: 2.5 | U2: 46069.292 | V2: CD Pouso Alegre Ultrapão | W2: 0 | X2: 28000 | Y2: Diego
A3: 46066.424 | B3: 555555 | C3: 14 - PPY - VARGINHA | D3: 555555 | E3: 46065.548 | F3: ULP0002 | G3: 9999999 | H3: 47380171000157 | I3: CD Guarulhos (Ultrapão) | K3: Ultrapão Transportes | L3: Avenida Faustino Ramalho | M3: Vila Galvão | N3: Guarulhos | O3: 2000 | P3: GRAMPEADOR | Q3: 10 | S3: CX | T3: 3.2 | U3: 46069.292 | V3: CD Pouso Alegre Ultrapão | W3: 0 | X3: 28000 | Y3: Diego
A4: 46071.487 | B4: 641160 | C4: 36 - GRU - ACLIMAÇÃO | D4: 18711426 | E4: 46071.609 | F4: SEG0002 | G4: 1722430201 | H4: 26563652080059 | I4: OXXO BETO | J4: Oxxo | K4: Ultrapão Transportes | L4: RUA ASTORGA, 482 LOJA CJ 460 R JANDAIA SUL | M4: VILA GUILHERMINA | N4: São Paulo | O4: 01.01.0001 | P4: MASSA CONGELADA DE PAO FRANCES RAPIDA - 5KG | Q4: 40 | R4: 0 | S4: PT | T4: 0 | U4: 46071.417 | V4: CD Guarulhos Ultrapão (Distribuidora) | W4: 0 | X4: 4000 | Y4: Vicente Varela da Silva Junior
A5: 46071.487 | B5: 641160 | C5: 36 - GRU - ACLIMAÇÃO | D5: 18711426 | E5: 46071.609 | F5: SEG0002 | G5: 1722430201 | H5: 26563652080059 | I5: OXXO BETO | J5: Oxxo | K5: Ultrapão Transportes | L5: RUA ASTORGA, 482 LOJA CJ 460 R JANDAIA SUL | M5: VILA GUILHERMINA | N5: São Paulo | O5: 01.09.0012 | P5: PAO FRANCES HOMEBAKE 3,24KG - 12 UNIDADES 270G | Q5: 1 | R5: 0 | S5: CX | T5: 0 | U5: 46071.417 | V5: CD Guarulhos Ultrapão (Distribuidora) | W5: 0 | X5: 4000 | Y5: Vicente Varela da Silva Junior
A6: 46071.739 | B6: 641511 | C6: 64 - GRU - SÃO CAETANO DO SUL | E6: 46070.857 | F6: SEG0001 | G6: 1714870201 | H6: 26563652046705 | I6: OXXO AMAROI | J6: Oxxo | K6: Ultrapão Transportes | L6: R AMAZONAS, 422 | M6: Centro | N6: São Caetano do Sul | O6: 01.01.0001 | P6: MASSA CONGELADA DE PAO FRANCES RAPIDA - 5KG | Q6: 7 | R6: 10 | S6: PT | T6: 57.336 | U6: 46072.292 | V6: CD Guarulhos Ultrapão (Distribuidora) | W6: 717.31 | X6: 4000 | Y6: Joaquim Martins dos Santos
A7: 46071.739 | B7: 641511 | C7: 64 - GRU - SÃO CAETANO DO SUL | E7: 46070.857 | F7: SEG0001 | G7: 1714870201 | H7: 26563652046705 | I7: OXXO AMAROI | J7: Oxxo | K7: Ultrapão Transportes | L7: R AMAZONAS, 422 | M7: Centro | N7: São Caetano do Sul | O7: 01.02.0007 | P7: MASSA CONGELADA DE PAO FRANCES COM GRAOS RAPIDA - 5KG | Q7: 1 | R7: 10 | S7: PT | T7: 57.336 | U7: 46072.292 | V7: CD Guarulhos Ultrapão (Distribuidora) | W7: 717.31 | X7: 4000 | Y7: Joaquim Martins dos Santos
A8: 46071.739 | B8: 641511 | C8: 64 - GRU - SÃO CAETANO DO SUL | E8: 46070.857 | F8: SEG0001 | G8: 1714870201 | H8: 26563652046705 | I8: OXXO AMAROI | J8: Oxxo | K8: Ultrapão Transportes | L8: R AMAZONAS, 422 | M8: Centro | N8: São Caetano do Sul | O8: 01.04.0008 | P8: PAO DE QUEIJO EMPANADO 30G - CX 10KG | Q8: 1 | R8: 10 | S8: CX | T8: 57.336 | U8: 46072.292 | V8: CD Guarulhos Ultrapão (Distribuidora) | W8: 717.31 | X8: 4000 | Y8: Joaquim Martins dos Santos
A9: 46071.739 | B9: 641511 | C9: 64 - GRU - SÃO CAETANO DO SUL | E9: 46070.857 | F9: SEG0001 | G9: 1714870201 | H9: 26563652046705 | I9: OXXO AMAROI | J9: Oxxo | K9: Ultrapão Transportes | L9: R AMAZONAS, 422 | M9: Centro | N9: São Caetano do Sul | O9: 02.01.0005 | P9: PAO DE QUEIJO FORNO DE MINAS ASSADO CONGELADO MAX LANCHE | Q9: 1 | R9: 10 | S9: CX | T9: 57.336 | U9: 46072.292 | V9: CD Guarulhos Ultrapão (Distribuidora) | W9: 717.31 | X9: 4000 | Y9: Joaquim Martins dos Santos
A10: 46071.739 | B10: 641511 | C10: 64 - GRU - SÃO CAETANO DO SUL | E10: 46072.773 | F10: SEG0001 | G10: 1725780201 | H10: 26563652029703 | I10: OXXO ATELIER | J10: Oxxo | K10: Ultrapão Transportes | L10: R SAO PAULO, 881 | M10: Santo Antônio | N10: São Caetano do Sul | O10: 01.01.0001 | P10: MASSA CONGELADA DE PAO FRANCES RAPIDA - 5KG | Q10: 14 | R10: 0 | S10: PT | T10: 70.252 | U10: 46072.292 | V10: CD Guarulhos Ultrapão (Distribuidora) | W10: 478.66 | X10: 4000 | Y10: Joaquim Martins dos Santos
A11: 46071.739 | B11: 641511 | C11: 64 - GRU - SÃO CAETANO DO SUL | E11: 46072.773 | F11: SEG0001 | G11: 1723350201 | H11: 26563652040006 | I11: OXXO BETTIN | J11: Oxxo | K11: Ultrapão Transportes | L11: R COSTA BARROS, 1890 | M11: Parque São Lucas | N11: São Paulo | O11: 01.01.0001 | P11: MASSA CONGELADA DE PAO FRANCES RAPIDA - 5KG | Q11: 9 | R11: 0 | S11: PT | T11: 50.162 | U11: 46072.292 | V11: CD Guarulhos Ultrapão (Distribuidora) | W11: 356.72 | X11: 4000 | Y11: Joaquim Martins dos Santos
A12: 46071.739 | B12: 641511 | C12: 64 - GRU - SÃO CAETANO DO SUL | E12: 46072.773 | F12: SEG0001 | G12: 1723350201 | H12: 26563652040006 | I12: OXXO BETTIN | J12: Oxxo | K12: Ultrapão Transportes | L12: R COSTA BARROS, 1890 | M12: Parque São Lucas | N12: São Paulo | O12: 01.02.0007 | P12: MASSA CONGELADA DE PAO FRANCES COM GRAOS RAPIDA - 5KG | Q12: 1 | R12: 0 | S12: PT | T12: 50.162 | U12: 46072.292 | V12: CD Guarulhos Ultrapão (Distribuidora) | W12: 356.72 | X12: 4000 | Y12: Joaquim Martins dos Santos
A13: 46071.739 | B13: 641511 | C13: 64 - GRU - SÃO CAETANO DO SUL | E13: 46072.773 | F13: SEG0001 | G13: 1723430201 | H13: 26563652067540 | I13: OXXO PORFIRIO DA PAZ | J13: Oxxo | K13: Ultrapão Transportes | M13: Vila Bancaria | N13: São Paulo | O13: 01.01.0001 | P13: MASSA CONGELADA DE PAO FRANCES RAPIDA - 5KG | Q13: 3 | R13: 0 | S13: PT | T13: 25.684 | U13: 46072.292 | V13: CD Guarulhos Ultrapão (Distribuidora) | W13: 363.57 | X13: 4000 | Y13: Joaquim Martins dos Santos
A14: 46071.739 | B14: 641511 | C14: 64 - GRU - SÃO CAETANO DO SUL | E14: 46072.773 | F14: SEG0001 | G14: 1723430201 | H14: 26563652067540 | I14: OXXO PORFIRIO DA PAZ | J14: Oxxo | K14: Ultrapão Transportes | M14: Vila Bancaria | N14: São Paulo | O14: 01.04.0066 | P14: MASSA CONGELADA DE PÃO DE QUEIJO RECHEADO DE REQUEIJÃO 65G ? CX 10 KG ? 5 UN DE 2 KG | Q14: 1 | R14: 0 | S14: CX | T14: 25.684 | U14: 46072.292 | V14: CD Guarulhos Ultrapão (Distribuidora) | W14: 363.57 | X14: 4000 | Y14: Joaquim Martins dos Santos
A15: 46071.739 | B15: 641511 | C15: 64 - GRU - SÃO CAETANO DO SUL | E15: 46072.773 | F15: SEG0001 | G15: 1725940201 | H15: 26563652032674 | I15: OXXO SERAFIM ESTACAO | J15: Oxxo | K15: Ultrapão Transportes | M15: Centro | N15: São Caetano do Sul | O15: 01.01.0001 | P15: MASSA CONGELADA DE PAO FRANCES RAPIDA - 5KG | Q15: 10 | R15: 0 | S15: PT | T15: 50.18 | U15: 46072.292 | V15: CD Guarulhos Ultrapão (Distribuidora) | W15: 341.9 | X15: 4000 | Y15: Joaquim Martins dos Santos
A16: 46071.739 | B16: 641511 | C16: 64 - GRU - SÃO CAETANO DO SUL | E16: 46072.773 | F16: SEG0001 | G16: 1724030201 | H16: 26563652045300 | I16: OXXO ANTERO | J16: Oxxo | K16: Ultrapão Transportes | L16: RUA DOMINGOS AFONSO, 398 | M16: Santa Clara | N16: São Paulo | O16: 01.01.0001 | P16: MASSA CONGELADA DE PAO FRANCES RAPIDA - 5KG | Q16: 9 | R16: 0 | S16: PT | T16: 50.162 | U16: 46072.292 | V16: CD Guarulhos Ultrapão (Distribuidora) | W16: 356.72 | X16: 4000 | Y16: Joaquim Martins dos Santos
A17: 46071.739 | B17: 641511 | C17: 64 - GRU - SÃO CAETANO DO SUL | E17: 46072.773 | F17: SEG0001 | G17: 1724030201 | H17: 26563652045300 | I17: OXXO ANTERO | J17: Oxxo | K17: Ultrapão Transportes | L17: RUA DOMINGOS AFONSO, 398 | M17: Santa Clara | N17: São Paulo | O17: 01.02.0007 | P17: MASSA CONGELADA DE PAO FRANCES COM GRAOS RAPIDA - 5KG | Q17: 1 | R17: 0 | S17: PT | T17: 50.162 | U17: 46072.292 | V17: CD Guarulhos Ultrapão (Distribuidora) | W17: 356.72 | X17: 4000 | Y17: Joaquim Martins dos Santos
A18: 46071.739 | B18: 641511 | C18: 64 - GRU - SÃO CAETANO DO SUL | E18: 46072.773 | F18: SEG0001 | G18: 1726120201 | H18: 26563652060023 | I18: OXXO FATIMA CAETANO | J18: Oxxo | K18: Ultrapão Transportes | M18: Santa Paula | N18: São Caetano do Sul | O18: 01.01.0001 | P18: MASSA CONGELADA DE PAO FRANCES RAPIDA - 5KG | Q18: 8 | R18: 0 | S18: PT | T18: 52.354 | U18: 46072.292 | V18: CD Guarulhos Ultrapão (Distribuidora) | W18: 576.78 | X18: 4000 | Y18: Joaquim Martins dos Santos
A19: 46071.739 | B19: 641511 | C19: 64 - GRU - SÃO CAETANO DO SUL | E19: 46072.773 | F19: SEG0001 | G19: 1726120201 | H19: 26563652060023 | I19: OXXO FATIMA CAETANO | J19: Oxxo | K19: Ultrapão Transportes | M19: Santa Paula | N19: São Caetano do Sul | O19: 01.02.0007 | P19: MASSA CONGELADA DE PAO FRANCES COM GRAOS RAPIDA - 5KG | Q19: 1 | R19: 0 | S19: PT | T19: 52.354 | U19: 46072.292 | V19: CD Guarulhos Ultrapão (Distribuidora) | W19: 576.78 | X19: 4000 | Y19: Joaquim Martins dos Santos
A20: 46071.739 | B20: 641511 | C20: 64 - GRU - SÃO CAETANO DO SUL | E20: 46072.773 | F20: SEG0001 | G20: 1726120201 | H20: 26563652060023 | I20: OXXO FATIMA CAETANO | J20: Oxxo | K20: Ultrapão Transportes | M20: Santa Paula | N20: São Caetano do Sul | O20: 02.01.0005 | P20: PAO DE QUEIJO FORNO DE MINAS ASSADO CONGELADO MAX LANCHE | Q20: 1 | R20: 0 | S20: CX | T20: 52.354 | U20: 46072.292 | V20: CD Guarulhos Ultrapão (Distribuidora) | W20: 576.78 | X20: 4000 | Y20: Joaquim Martins dos Santos
A21: 46071.739 | B21: 641511 | C21: 64 - GRU - SÃO CAETANO DO SUL | E21: 46072.773 | F21: SEG0001 | G21: 1726140201 | H21: 26563652038109 | I21: OXXO GOIAS CAFE | J21: Oxxo | K21: Ultrapão Transportes | M21: Santo Antônio | N21: São Caetano do Sul | O21: 01.01.0001 | P21: MASSA CONGELADA DE PAO FRANCES RAPIDA - 5KG | Q21: 6 | R21: 0 | S21: PT | T21: 40.108 | U21: 46072.292 | V21: CD Guarulhos Ultrapão (Distribuidora) | W21: 379.86 | X21: 4000 | Y21: Joaquim Martins dos Santos
A22: 46071.739 | B22: 641511 | C22: 64 - GRU - SÃO CAETANO DO SUL | E22: 46072.773 | F22: SEG0001 | G22: 1726140201 | H22: 26563652038109 | I22: OXXO GOIAS CAFE | J22: Oxxo | K22: Ultrapão Transportes | M22: Santo Antônio | N22: São Caetano do Sul | O22: 01.04.0008 | P22: PAO DE QUEIJO EMPANADO 30G - CX 10KG | Q22: 1 | R22: 0 | S22: CX | T22: 40.108 | U22: 46072.292 | V22: CD Guarulhos Ultrapão (Distribuidora) | W22: 379.86 | X22: 4000 | Y22: Joaquim Martins dos Santos
A23: 46071.739 | B23: 641511 | C23: 64 - GRU - SÃO CAETANO DO SUL | E23: 46072.773 | F23: SEG0001 | G23: 1724290201 | H23: 26563652019147 | I23: OXXO SOLIDONIO | J23: Oxxo | K23: Ultrapão Transportes | M23: Vila Ema | N23: São Paulo | O23: 01.01.0001 | P23: MASSA CONGELADA DE PAO FRANCES RAPIDA - 5KG | Q23: 4 | R23: 0 | S23: PT | T23: 25.072 | U23: 46072.292 | V23: CD Guarulhos Ultrapão (Distribuidora) | W23: 185.77 | X23: 4000 | Y23: Joaquim Martins dos Santos
A24: 46071.739 | B24: 641511 | C24: 64 - GRU - SÃO CAETANO DO SUL | E24: 46072.773 | F24: SEG0001 | G24: 1724290201 | H24: 26563652019147 | I24: OXXO SOLIDONIO | J24: Oxxo | K24: Ultrapão Transportes | M24: Vila Ema | N24: São Paulo | O24: 01.02.0007 | P24: MASSA CONGELADA DE PAO FRANCES COM GRAOS RAPIDA - 5KG | Q24: 1 | R24: 0 | S24: PT | T24: 25.072 | U24: 46072.292 | V24: CD Guarulhos Ultrapão (Distribuidora) | W24: 185.77 | X24: 4000 | Y24: Joaquim Martins dos Santos
A25: 46071.739 | B25: 641511 | C25: 64 - GRU - SÃO CAETANO DO SUL | E25: 46072.773 | F25: SEG0001 | G25: 1724430201 | H25: 26563652077260 | I25: OXXO PLANALTO CRUZ | J25: Oxxo | K25: Ultrapão Transportes | M25: JARDIM ADUTORA | N25: São Paulo | O25: 01.01.0001 | P25: MASSA CONGELADA DE PAO FRANCES RAPIDA - 5KG | Q25: 9 | R25: 0 | S25: PT | T25: 48.362 | U25: 46072.292 | V25: CD Guarulhos Ultrapão (Distribuidora) | W25: 373.71 | X25: 4000 | Y25: Joaquim Martins dos Santos
A26: 46071.739 | B26: 641511 | C26: 64 - GRU - SÃO CAETANO DO SUL | E26: 46072.773 | F26: SEG0001 | G26: 1724430201 | H26: 26563652077260 | I26: OXXO PLANALTO CRUZ | J26: Oxxo | K26: Ultrapão Transportes | M26: JARDIM ADUTORA | N26: São Paulo | O26: 01.10.0013 | P26: MINI BAGUETE FRANCESA LEVIASSA - PT 0,240 KG - CX 2,88 KG - 12 UN | Q26: 1 | R26: 0 | S26: CX | T26: 48.362 | U26: 46072.292 | V26: CD Guarulhos Ultrapão (Distribuidora) | W26: 373.71 | X26: 4000 | Y26: Joaquim Martins dos Santos
A27: 46071.739 | B27: 641511 | C27: 64 - GRU - SÃO CAETANO DO SUL | E27: 46072.773 | F27: SEG0001 | G27: 1726350201 | H27: 26563652028642 | I27: OXXO MONTE ALEGRE | J27: Oxxo | K27: Ultrapão Transportes | M27: Santo Antônio | N27: São Caetano do Sul | O27: 01.01.0001 | P27: MASSA CONGELADA DE PAO FRANCES RAPIDA - 5KG | Q27: 8 | R27: 0 | S27: PT | T27: 50.144 | U27: 46072.292 | V27: CD Guarulhos Ultrapão (Distribuidora) | W27: 371.54 | X27: 4000 | Y27: Joaquim Martins dos Santos
A28: 46071.739 | B28: 641511 | C28: 64 - GRU - SÃO CAETANO DO SUL | E28: 46072.773 | F28: SEG0001 | G28: 1726350201 | H28: 26563652028642 | I28: OXXO MONTE ALEGRE | J28: Oxxo | K28: Ultrapão Transportes | M28: Santo Antônio | N28: São Caetano do Sul | O28: 01.02.0007 | P28: MASSA CONGELADA DE PAO FRANCES COM GRAOS RAPIDA - 5KG | Q28: 2 | R28: 0 | S28: PT | T28: 50.144 | U28: 46072.292 | V28: CD Guarulhos Ultrapão (Distribuidora) | W28: 371.54 | X28: 4000 | Y28: Joaquim Martins dos Santos
A29: 46071.739 | B29: 641511 | C29: 64 - GRU - SÃO CAETANO DO SUL | E29: 46072.773 | F29: SEG0001 | G29: 1726370201 | H29: 26563652046705 | I29: OXXO AMAROI | J29: Oxxo | K29: Ultrapão Transportes | L29: R AMAZONAS, 422 | M29: Centro | N29: São Caetano do Sul | O29: 01.01.0001 | P29: MASSA CONGELADA DE PAO FRANCES RAPIDA - 5KG | Q29: 5 | R29: 0 | S29: PT | T29: 42.06 | U29: 46072.292 | V29: CD Guarulhos Ultrapão (Distribuidora) | W29: 535.37 | X29: 4000 | Y29: Joaquim Martins dos Santos
A30: 46071.739 | B30: 641511 | C30: 64 - GRU - SÃO CAETANO DO SUL | E30: 46072.773 | F30: SEG0001 | G30: 1726370201 | H30: 26563652046705 | I30: OXXO AMAROI | J30: Oxxo | K30: Ultrapão Transportes | L30: R AMAZONAS, 422 | M30: Centro | N30: São Caetano do Sul | O30: 01.02.0007 | P30: MASSA CONGELADA DE PAO FRANCES COM GRAOS RAPIDA - 5KG | Q30: 2 | R30: 0 | S30: PT | T30: 42.06 | U30: 46072.292 | V30: CD Guarulhos Ultrapão (Distribuidora) | W30: 535.37 | X30: 4000 | Y30: Joaquim Martins dos Santos
A31: 46071.739 | B31: 641511 | C31: 64 - GRU - SÃO CAETANO DO SUL | E31: 46072.773 | F31: SEG0001 | G31: 1726370201 | H31: 26563652046705 | I31: OXXO AMAROI | J31: Oxxo | K31: Ultrapão Transportes | L31: R AMAZONAS, 422 | M31: Centro | N31: São Caetano do Sul | O31: 02.01.0004 | P31: PAO DE QUEIJO FORNO DE MINAS ASSADO CONGELADO RECHEADO REQUEIJAO MAX LANCHE | Q31: 1 | R31: 0 | S31: CX | T31: 42.06 | U31: 46072.292 | V31: CD Guarulhos Ultrapão (Distribuidora) | W31: 535.37 | X31: 4000 | Y31: Joaquim Martins dos Santos
A32: 46071.739 | B32: 641511 | C32: 64 - GRU - SÃO CAETANO DO SUL | E32: 46072.773 | F32: SEG0001 | G32: 1726510201 | H32: 26563652079395 | I32: OXXO QUINTINO GOIAS | J32: Oxxo | K32: Ultrapão Transportes | M32: Barcelona | N32: São Caetano do Sul | O32: 01.01.0001 | P32: MASSA CONGELADA DE PAO FRANCES RAPIDA - 5KG | Q32: 5 | R32: 0 | S32: PT | T32: 42.06 | U32: 46072.292 | V32: CD Guarulhos Ultrapão (Distribuidora) | W32: 612.07 | X32: 4000 | Y32: Joaquim Martins dos Santos
A33: 46071.739 | B33: 641511 | C33: 64 - GRU - SÃO CAETANO DO SUL | E33: 46072.773 | F33: SEG0001 | G33: 1726510201 | H33: 26563652079395 | I33: OXXO QUINTINO GOIAS | J33: Oxxo | K33: Ultrapão Transportes | M33: Barcelona | N33: São Caetano do Sul | O33: 01.04.0008 | P33: PAO DE QUEIJO EMPANADO 30G - CX 10KG | Q33: 1 | R33: 0 | S33: CX | T33: 42.06 | U33: 46072.292 | V33: CD Guarulhos Ultrapão (Distribuidora) | W33: 612.07 | X33: 4000 | Y33: Joaquim Martins dos Santos
A34: 46071.739 | B34: 641511 | C34: 64 - GRU - SÃO CAETANO DO SUL | E34: 46072.773 | F34: SEG0001 | G34: 1726510201 | H34: 26563652079395 | I34: OXXO QUINTINO GOIAS | J34: Oxxo | K34: Ultrapão Transportes | M34: Barcelona | N34: São Caetano do Sul | O34: 02.01.0004 | P34: PAO DE QUEIJO FORNO DE MINAS ASSADO CONGELADO RECHEADO REQUEIJAO MAX LANCHE | Q34: 1 | R34: 0 | S34: CX | T34: 42.06 | U34: 46072.292 | V34: CD Guarulhos Ultrapão (Distribuidora) | W34: 612.07 | X34: 4000 | Y34: Joaquim Martins dos Santos
A35: 46071.739 | B35: 641511 | C35: 64 - GRU - SÃO CAETANO DO SUL | E35: 46072.773 | F35: SEG0001 | G35: 1726530201 | H35: 26563652059793 | I35: OXXO HELO SALGADO | J35: Oxxo | K35: Ultrapão Transportes | M35: Fundação, | N35: São Caetano do Sul | O35: 01.01.0001 | P35: MASSA CONGELADA DE PAO FRANCES RAPIDA - 5KG | Q35: 3 | R35: 0 | S35: PT | T35: 40.684 | U35: 46072.292 | V35: CD Guarulhos Ultrapão (Distribuidora) | W35: 510.6 | X35: 4000 | Y35: Joaquim Martins dos Santos
A36: 46071.739 | B36: 641511 | C36: 64 - GRU - SÃO CAETANO DO SUL | E36: 46072.773 | F36: SEG0001 | G36: 1726530201 | H36: 26563652059793 | I36: OXXO HELO SALGADO | J36: Oxxo | K36: Ultrapão Transportes | M36: Fundação, | N36: São Caetano do Sul | O36: 01.02.0007 | P36: MASSA CONGELADA DE PAO FRANCES COM GRAOS RAPIDA - 5KG | Q36: 3 | R36: 0 | S36: PT | T36: 40.684 | U36: 46072.292 | V36: CD Guarulhos Ultrapão (Distribuidora) | W36: 510.6 | X36: 4000 | Y36: Joaquim Martins dos Santos
A37: 46071.739 | B37: 641511 | C37: 64 - GRU - SÃO CAETANO DO SUL | E37: 46072.773 | F37: SEG0001 | G37: 1726530201 | H37: 26563652059793 | I37: OXXO HELO SALGADO | J37: Oxxo | K37: Ultrapão Transportes | M37: Fundação, | N37: São Caetano do Sul | O37: 01.04.0066 | P37: MASSA CONGELADA DE PÃO DE QUEIJO RECHEADO DE REQUEIJÃO 65G ? CX 10 KG ? 5 UN DE 2 KG | Q37: 1 | R37: 0 | S37: CX | T37: 40.684 | U37: 46072.292 | V37: CD Guarulhos Ultrapão (Distribuidora) | W37: 510.6 | X37: 4000 | Y37: Joaquim Martins dos Santos
A38: 46071.739 | B38: 641512 | C38: GRU - CD CONFIANÇA | E38: 46070.797 | F38: ELQ2549 | G38: 1708280201 | H38: 53045266000389 | I38: REDE CONFIANÇA DEPOSITO CENTRAL LJ 100 | J38: Varejo | K38: Wesley Odilon Ribeiro | L38: RUA INACIO CONCEICAO VEIRA, 25-75 | M38: VILA AVIACAO | N38: Bauru | O38: 01.09.0007 | P38: CIABATTA HOMEBAKE TRADICIONAL 3,6KG - 12 UNIDADES 300G | Q38: 34 | R38: 0 | S38: CX | T38: 548.16 | U38: 46072.292 | V38: CD Guarulhos Ultrapão (Distribuidora) | W38: 12403.44 | X38: 2500 | Y38: Wesley Odilon Ribeiro
A39: 46071.739 | B39: 641512 | C39: GRU - CD CONFIANÇA | E39: 46070.797 | F39: ELQ2549 | G39: 1708280201 | H39: 53045266000389 | I39: REDE CONFIANÇA DEPOSITO CENTRAL LJ 100 | J39: Varejo | K39: Wesley Odilon Ribeiro | L39: RUA INACIO CONCEICAO VEIRA, 25-75 | M39: VILA AVIACAO | N39: Bauru | O39: 01.09.0008 | P39: CIABATTA HOMEBAKE COM GRAOS 3,6KG - 12 UNIDADES 300G | Q39: 32 | R39: 0 | S39: CX | T39: 548.16 | U39: 46072.292 | V39: CD Guarulhos Ultrapão (Distribuidora) | W39: 12403.44 | X39: 2500 | Y39: Wesley Odilon Ribeiro
A40: 46071.739 | B40: 641512 | C40: GRU - CD CONFIANÇA | E40: 46070.797 | F40: ELQ2549 | G40: 1708280201 | H40: 53045266000389 | I40: REDE CONFIANÇA DEPOSITO CENTRAL LJ 100 | J40: Varejo | K40: Wesley Odilon Ribeiro | L40: RUA INACIO CONCEICAO VEIRA, 25-75 | M40: VILA AVIACAO | N40: Bauru | O40: 01.09.0012 | P40: PAO FRANCES HOMEBAKE 3,24KG - 12 UNIDADES 270G | Q40: 72 | R40: 0 | S40: CX | T40: 548.16 | U40: 46072.292 | V40: CD Guarulhos Ultrapão (Distribuidora) | W40: 12403.44 | X40: 2500 | Y40: Wesley Odilon Ribeiro
...

Sheet TODAS AS PLACAS
A1: FROTA | B1: PLACA: | C1: CAPACIDADE: | D1: TIPO: | E1: Rodízio
A2: PROPRIA | B2: SWY3E25 | C2: 4200 | D2: 46115 | E2: Quarta-feira
A3: PROPRIA | B3: EZO8E62 | C3: 4200 | D3: 46115 | E3: Segunda-feira
A4: PROPRIA | B4: FED2A32 | C4: 4200 | D4: 46115 | E4: Segunda-feira
A5: PROPRIA | B5: STS8F92 | C5: 4200 | D5: 46115 | E5: Segunda-feira
A6: PROPRIA | B6: SVZ2D07 | C6: 4200 | D6: 46115 | E6: Quinta-feira
A7: PROPRIA | B7: SSV3J72 | C7: 4200 | D7: 46115 | E7: Segunda-feira
A8: PROPRIA | B8: ENI7G21 | C8: 4200 | D8: 46115 | E8: Segunda-feira
A9: PROPRIA | B9: SWB3F77 | C9: 4200 | D9: 46115 | E9: Quinta-feira
A10: PROPRIA | B10: SVZ3G77 | C10: 4200 | D10: 46115 | E10: Quinta-feira
A11: PROPRIA | B11: SWI6E54 | C11: 4200 | D11: 46115 | E11: Terça-feira
A12: PROPRIA | B12: EOF7G31 | C12: 4200 | D12: 46115 | E12: Segunda-feira
A13: PROPRIA | B13: SXN4A56 | C13: 4500/ 3 Palet | D13: 46115 | E13: Quarta-feira
A14: PROPRIA | B14: SXN5F36 | C14: 4500/ 8 Palet | D14: 46115 | E14: Quarta-feira
A15: PROPRIA | B15: SXM5I76 | C15: 4500/ 8 Palet | D15: 46115 | E15: Quarta-feira
A16: PROPRIA | B16: RFS3I44 | C16: 1500 / 2 Palet | D16: 46115 | E16: Terça-feira
A17: PROPRIA | B17: SEG0001 | D17: 46115 | E17: Segunda-feira
A18: PROPRIA | B18: SEG0002 | D18: 46115 | E18: Segunda-feira
A19: PROPRIA | B19: IXM3E88 | C19: 8000 | D19: TRUCK | E19: Sexta-feira
A20: AGREGADO | B20: FSS4C66 | C20: 2700 | D20: 46115 | E20: Quarta-feira
A21: AGREGADO | B21: FUO2I21 | C21: 2700 | D21: 46115 | E21: Segunda-feira
A22: AGREGADO | B22: FTF2H12 | C22: 2500 | D22: 46115 | E22: Segunda-feira
A23: AGREGADO | B23: SVA5J31 | C23: 2500 | D23: 46115 | E23: Segunda-feira
A24: TERCEIRO | B24: EWJ3E57 | C24: 2500 | D24: VUC | E24: Quinta-feira
A25: TERCEIRO | B25: ELQ2549 | C25: 2500 | D25: VUC | E25: Sexta-feira
A26: TERCEIRO | B26: EMU1F41 | C26: 2500 | D26: VUC | E26: Segunda-feira
A27: TERCEIRO | B27: DTD1C82 | C27: 1500 | D27: VAN | E27: Segunda-feira
A28: TERCEIRO | B28: FBV9B83 | C28: 700 | D28: FIORINO | E28: Terça-feira
A29: TERCEIRO | B29: EFW3195 | C29: 1500 | D29: HR | E29: Quarta-feira
A30: TERCEIRO | B30: FSS4C65 | C30: 1500 | D30: HR | E30: Quarta-feira
A31: TERCEIRO | B31: HBN8E36 | C31: 1500 | D31: HR | E31: Quarta-feira
A32: TERCEIRO | B32: FUO8F70 | C32: 500 | D32: FIORINO | E32: Sexta-feira
A33: TERCEIRO | B33: EUG6C39 | C33: 1500 | D33: HR | E33: Sexta-feira
A34: TERCEIRO | B34: FQQ1H88 | C34: 500 | D34: FIORINO | E34: Quinta-feira
A35: TERCEIRO | B35: ONL6155 | C35: 1500 | D35: HR | E35: Quarta-feira
... A38: TERCEIRO | B38: RTV5C90 | C38: 500 | D38: FIORINO | E38: Sexta-feira
A39: PROPRIA | B39: GAF9F72 | C39: 4500/ 8 Palet | D39: 46115 | E39: Segunda-feira

Sheet DIVERGÊNCIAS
A1: CÓDIGO DE BARRAS | B1: PRODUTO | C1: QUANTIDADE BIPADA | D1: QUANTIDADE ROMANEIO | E1: DIFERENÇA | F1: TIPO
A2: =IFERROR(_xlfn.SINGLE(INDEX('ROMANEIO POR ITEM'!#REF!, SMALL(IF(_xlfn.SINGLE('ROMANEIO POR ITEM'!#REF!)<>0,_xlfn.SINGLE( ROW('ROMANEIO POR ITEM'!#REF!))-ROW('ROMANEIO POR ITEM'!#REF!)+1), ROW(A1)))), "") | B2: =IF(A2="", "", VLOOKUP(A2, 'ROMANEIO POR ITEM'!#REF!, 2, FALSE)) | C2: =IF(A2="", "", VLOOKUP(A2, 'ROMANEIO POR ITEM'!#REF!, 3, FALSE)) | D2: =IF(A2="", "", VLOOKUP(A2, 'ROMANEIO POR ITEM'!#REF!, 4, FALSE)) | E2: =IF(A2="", "", VLOOKUP(A2, 'ROMANEIO POR ITEM'!#REF!, 5, FALSE)) | F2: =IF(A2="", "", VLOOKUP(A2, 'ROMANEIO POR ITEM'!#REF!, 6, FALSE))
A3: =IFERROR(_xlfn.SINGLE(INDEX('ROMANEIO POR ITEM'!#REF!, SMALL(IF(_xlfn.SINGLE('ROMANEIO POR ITEM'!#REF!)<>0,_xlfn.SINGLE( ROW('ROMANEIO POR ITEM'!#REF!))-ROW('ROMANEIO POR ITEM'!#REF!)+1), ROW(A2)))), "") | B3: =IF(A3="", "", VLOOKUP(A3, 'ROMANEIO POR ITEM'!#REF!, 2, FALSE)) | C3: =IF(A3="", "", VLOOKUP(A3, 'ROMANEIO POR ITEM'!#REF!, 3, FALSE)) | D3: =IF(A3="", "", VLOOKUP(A3, 'ROMANEIO POR ITEM'!#REF!, 4, FALSE)) | E3: =IF(A3="", "", VLOOKUP(A3, 'ROMANEIO POR ITEM'!#REF!, 5, FALSE)) | F3: =IF(A3="", "", VLOOKUP(A3, 'ROMANEIO POR ITEM'!#REF!, 6, FALSE))
A4: =IFERROR(_xlfn.SINGLE(INDEX('ROMANEIO POR ITEM'!#REF!, SMALL(IF(_xlfn.SINGLE('ROMANEIO POR ITEM'!#REF!)<>0,_xlfn.SINGLE( ROW('ROMANEIO POR ITEM'!#REF!))-ROW('ROMANEIO POR ITEM'!#REF!)+1), ROW(A3)))), "") | B4: =IF(A4="", "", VLOOKUP(A4, 'ROMANEIO POR ITEM'!#REF!, 2, FALSE)) | C4: =IF(A4="", "", VLOOKUP(A4, 'ROMANEIO POR ITEM'!#REF!, 3, FALSE)) | D4: =IF(A4="", "", VLOOKUP(A4, 'ROMANEIO POR ITEM'!#REF!, 4, FALSE)) | E4: =IF(A4="", "", VLOOKUP(A4, 'ROMANEIO POR ITEM'!#REF!, 5, FALSE)) | F4: =IF(A4="", "", VLOOKUP(A4, 'ROMANEIO POR ITEM'!#REF!, 6, FALSE))
A5: =IFERROR(_xlfn.SINGLE(INDEX('ROMANEIO POR ITEM'!#REF!, SMALL(IF(_xlfn.SINGLE('ROMANEIO POR ITEM'!#REF!)<>0,_xlfn.SINGLE( ROW('ROMANEIO POR ITEM'!#REF!))-ROW('ROMANEIO POR ITEM'!#REF!)+1), ROW(A4)))), "") | B5: =IF(A5="", "", VLOOKUP(A5, 'ROMANEIO POR ITEM'!#REF!, 2, FALSE)) | C5: =IF(A5="", "", VLOOKUP(A5, 'ROMANEIO POR ITEM'!#REF!, 3, FALSE)) | D5: =IF(A5="", "", VLOOKUP(A5, 'ROMANEIO POR ITEM'!#REF!, 4, FALSE)) | E5: =IF(A5="", "", VLOOKUP(A5, 'ROMANEIO POR ITEM'!#REF!, 5, FALSE)) | F5: =IF(A5="", "", VLOOKUP(A5, 'ROMANEIO POR ITEM'!#REF!, 6, FALSE))
A6: =IFERROR(_xlfn.SINGLE(INDEX('ROMANEIO POR ITEM'!#REF!, SMALL(IF(_xlfn.SINGLE('ROMANEIO POR ITEM'!#REF!)<>0,_xlfn.SINGLE( ROW('ROMANEIO POR ITEM'!#REF!))-ROW('ROMANEIO POR ITEM'!#REF!)+1), ROW(A5)))), "") | B6: =IF(A6="", "", VLOOKUP(A6, 'ROMANEIO POR ITEM'!#REF!, 2, FALSE)) | C6: =IF(A6="", "", VLOOKUP(A6, 'ROMANEIO POR ITEM'!#REF!, 3, FALSE)) | D6: =IF(A6="", "", VLOOKUP(A6, 'ROMANEIO POR ITEM'!#REF!, 4, FALSE)) | E6: =IF(A6="", "", VLOOKUP(A6, 'ROMANEIO POR ITEM'!#REF!, 5, FALSE)) | F6: =IF(A6="", "", VLOOKUP(A6, 'ROMANEIO POR ITEM'!#REF!, 6, FALSE))
A7: =IFERROR(_xlfn.SINGLE(INDEX('ROMANEIO POR ITEM'!#REF!, SMALL(IF(_xlfn.SINGLE('ROMANEIO POR ITEM'!#REF!)<>0,_xlfn.SINGLE( ROW('ROMANEIO POR ITEM'!#REF!))-ROW('ROMANEIO POR ITEM'!#REF!)+1), ROW(A6)))), "") | B7: =IF(A7="", "", VLOOKUP(A7, 'ROMANEIO POR ITEM'!#REF!, 2, FALSE)) | C7: =IF(A7="", "", VLOOKUP(A7, 'ROMANEIO POR ITEM'!#REF!, 3, FALSE)) | D7: =IF(A7="", "", VLOOKUP(A7, 'ROMANEIO POR ITEM'!#REF!, 4, FALSE)) | E7: =IF(A7="", "", VLOOKUP(A7, 'ROMANEIO POR ITEM'!#REF!, 5, FALSE)) | F7: =IF(A7="", "", VLOOKUP(A7, 'ROMANEIO POR ITEM'!#REF!, 6, FALSE))
A8: =IFERROR(_xlfn.SINGLE(INDEX('ROMANEIO POR ITEM'!#REF!, SMALL(IF(_xlfn.SINGLE('ROMANEIO POR ITEM'!#REF!)<>0,_xlfn.SINGLE( ROW('ROMANEIO POR ITEM'!#REF!))-ROW('ROMANEIO POR ITEM'!#REF!)+1), ROW(A7)))), "") | B8: =IF(A8="", "", VLOOKUP(A8, 'ROMANEIO POR ITEM'!#REF!, 2, FALSE)) | C8: =IF(A8="", "", VLOOKUP(A8, 'ROMANEIO POR ITEM'!#REF!, 3, FALSE)) | D8: =IF(A8="", "", VLOOKUP(A8, 'ROMANEIO POR ITEM'!#REF!, 4, FALSE)) | E8: =IF(A8="", "", VLOOKUP(A8, 'ROMANEIO POR ITEM'!#REF!, 5, FALSE)) | F8: =IF(A8="", "", VLOOKUP(A8, 'ROMANEIO POR ITEM'!#REF!, 6, FALSE))
A9: =IFERROR(_xlfn.SINGLE(INDEX('ROMANEIO POR ITEM'!#REF!, SMALL(IF(_xlfn.SINGLE('ROMANEIO POR ITEM'!#REF!)<>0,_xlfn.SINGLE( ROW('ROMANEIO POR ITEM'!#REF!))-ROW('ROMANEIO POR ITEM'!#REF!)+1), ROW(A8)))), "") | B9: =IF(A9="", "", VLOOKUP(A9, 'ROMANEIO POR ITEM'!#REF!, 2, FALSE)) | C9: =IF(A9="", "", VLOOKUP(A9, 'ROMANEIO POR ITEM'!#REF!, 3, FALSE)) | D9: =IF(A9="", "", VLOOKUP(A9, 'ROMANEIO POR ITEM'!#REF!, 4, FALSE)) | E9: =IF(A9="", "", VLOOKUP(A9, 'ROMANEIO POR ITEM'!#REF!, 5, FALSE)) | F9: =IF(A9="", "", VLOOKUP(A9, 'ROMANEIO POR ITEM'!#REF!, 6, FALSE))
A10: =IFERROR(_xlfn.SINGLE(INDEX('ROMANEIO POR ITEM'!#REF!, SMALL(IF(_xlfn.SINGLE('ROMANEIO POR ITEM'!#REF!)<>0,_xlfn.SINGLE( ROW('ROMANEIO POR ITEM'!#REF!))-ROW('ROMANEIO POR ITEM'!#REF!)+1), ROW(A9)))), "") | B10: =IF(A10="", "", VLOOKUP(A10, 'ROMANEIO POR ITEM'!#REF!, 2, FALSE)) | C10: =IF(A10="", "", VLOOKUP(A10, 'ROMANEIO POR ITEM'!#REF!, 3, FALSE)) | D10: =IF(A10="", "", VLOOKUP(A10, 'ROMANEIO POR ITEM'!#REF!, 4, FALSE)) | E10: =IF(A10="", "", VLOOKUP(A10, 'ROMANEIO POR ITEM'!#REF!, 5, FALSE)) | F10: =IF(A10="", "", VLOOKUP(A10, 'ROMANEIO POR ITEM'!#REF!, 6, FALSE))
A11: =IFERROR(_xlfn.SINGLE(INDEX('ROMANEIO POR ITEM'!#REF!, SMALL(IF(_xlfn.SINGLE('ROMANEIO POR ITEM'!#REF!)<>0,_xlfn.SINGLE( ROW('ROMANEIO POR ITEM'!#REF!))-ROW('ROMANEIO POR ITEM'!#REF!)+1), ROW(A10)))), "") | B11: =IF(A11="", "", VLOOKUP(A11, 'ROMANEIO POR ITEM'!#REF!, 2, FALSE)) | C11: =IF(A11="", "", VLOOKUP(A11, 'ROMANEIO POR ITEM'!#REF!, 3, FALSE)) | D11: =IF(A11="", "", VLOOKUP(A11, 'ROMANEIO POR ITEM'!#REF!, 4, FALSE)) | E11: =IF(A11="", "", VLOOKUP(A11, 'ROMANEIO POR ITEM'!#REF!, 5, FALSE)) | F11: =IF(A11="", "", VLOOKUP(A11, 'ROMANEIO POR ITEM'!#REF!, 6, FALSE))
A12: =IFERROR(_xlfn.SINGLE(INDEX('ROMANEIO POR ITEM'!#REF!, SMALL(IF(_xlfn.SINGLE('ROMANEIO POR ITEM'!#REF!)<>0,_xlfn.SINGLE( ROW('ROMANEIO POR ITEM'!#REF!))-ROW('ROMANEIO POR ITEM'!#REF!)+1), ROW(A11)))), "") | B12: =IF(A12="", "", VLOOKUP(A12, 'ROMANEIO POR ITEM'!#REF!, 2, FALSE)) | C12: =IF(A12="", "", VLOOKUP(A12, 'ROMANEIO POR ITEM'!#REF!, 3, FALSE)) | D12: =IF(A12="", "", VLOOKUP(A12, 'ROMANEIO POR ITEM'!#REF!, 4, FALSE)) | E12: =IF(A12="", "", VLOOKUP(A12, 'ROMANEIO POR ITEM'!#REF!, 5, FALSE)) | F12: =IF(A12="", "", VLOOKUP(A12, 'ROMANEIO POR ITEM'!#REF!, 6, FALSE))
A13: =IFERROR(_xlfn.SINGLE(INDEX('ROMANEIO POR ITEM'!#REF!, SMALL(IF(_xlfn.SINGLE('ROMANEIO POR ITEM'!#REF!)<>0,_xlfn.SINGLE( ROW('ROMANEIO POR ITEM'!#REF!))-ROW('ROMANEIO POR ITEM'!#REF!)+1), ROW(A12)))), "") | B13: =IF(A13="", "", VLOOKUP(A13, 'ROMANEIO POR ITEM'!#REF!, 2, FALSE)) | C13: =IF(A13="", "", VLOOKUP(A13, 'ROMANEIO POR ITEM'!#REF!, 3, FALSE)) | D13: =IF(A13="", "", VLOOKUP(A13, 'ROMANEIO POR ITEM'!#REF!, 4, FALSE)) | E13: =IF(A13="", "", VLOOKUP(A13, 'ROMANEIO POR ITEM'!#REF!, 5, FALSE)) | F13: =IF(A13="", "", VLOOKUP(A13, 'ROMANEIO POR ITEM'!#REF!, 6, FALSE))
... A1000: =IFERROR(_xlfn.SINGLE(INDEX('ROMANEIO POR ITEM'!#REF!, SMALL(IF(_xlfn.SINGLE('ROMANEIO POR ITEM'!#REF!)<>0,_xlfn.SINGLE( ROW('ROMANEIO POR ITEM'!#REF!))-ROW('ROMANEIO POR ITEM'!#REF!)+1), ROW(A999)))), "") | B1000: =IF(A1000="", "", VLOOKUP(A1000, 'ROMANEIO POR ITEM'!#REF!, 2, FALSE)) | C1000: =IF(A1000="", "", VLOOKUP(A1000, 'ROMANEIO POR ITEM'!#REF!, 3, FALSE)) | D1000: =IF(A1000="", "", VLOOKUP(A1000, 'ROMANEIO POR ITEM'!#REF!, 4, FALSE)) | E1000: =IF(A1000="", "", VLOOKUP(A1000, 'ROMANEIO POR ITEM'!#REF!, 5, FALSE)) | F1000: =IF(A1000="", "", VLOOKUP(A1000, 'ROMANEIO POR ITEM'!#REF!, 6, FALSE))
